Internal Server Error: /forgot-password/
Traceback (most recent call last):
  File "C:\Users\admin\AppData\Local\Programs\Python\Python312\Lib\site-packages\django\core\handlers\exception.py", line 55, in inner
    response = get_response(request)
               ^^^^^^^^^^^^^^^^^^^^^
  File "C:\Users\admin\AppData\Local\Programs\Python\Python312\Lib\site-packages\django\core\handlers\base.py", line 197, in _get_response
    response = wrapped_callback(request, *callback_args, **callback_kwargs)
               ^^^^^^^^^^^^^^^^^^^^^^^^^^^^^^^^^^^^^^^^^^^^^^^^^^^^^^^^^^^^
  File "C:\Users\admin\siteworks\core\views.py", line 109, in forgot_password
    send_mail(
  File "C:\Users\admin\AppData\Local\Programs\Python\Python312\Lib\site-packages\django\core\mail\__init__.py", line 88, in send_mail
    return mail.send()
           ^^^^^^^^^^^
  File "C:\Users\admin\AppData\Local\Programs\Python\Python312\Lib\site-packages\django\core\mail\message.py", line 301, in send
    return self.get_connection(fail_silently).send_messages([self])
           ^^^^^^^^^^^^^^^^^^^^^^^^^^^^^^^^^^^^^^^^^^^^^^^^^^^^^^^^
  File "C:\Users\admin\AppData\Local\Programs\Python\Python312\Lib\site-packages\django\core\mail\backends\smtp.py", line 128, in send_messages
    new_conn_created = self.open()
                       ^^^^^^^^^^^
  File "C:\Users\admin\AppData\Local\Programs\Python\Python312\Lib\site-packages\django\core\mail\backends\smtp.py", line 95, in open
    self.connection.login(self.username, self.password)
  File "C:\Users\admin\AppData\Local\Programs\Python\Python312\Lib\smtplib.py", line 750, in login
    raise last_exception
  File "C:\Users\admin\AppData\Local\Programs\Python\Python312\Lib\smtplib.py", line 739, in login
    (code, resp) = self.auth(
                   ^^^^^^^^^^
  File "C:\Users\admin\AppData\Local\Programs\Python\Python312\Lib\smtplib.py", line 662, in auth
    raise SMTPAuthenticationError(code, resp)
smtplib.SMTPAuthenticationError: (535, b'5.7.8 Authentication failed')
"POST /forgot-password/ HTTP/1.1" 500 102454
Internal Server Error: /forgot-password/
Traceback (most recent call last):
  File "C:\Users\admin\siteworks\core\views.py", line 114, in forgot_password
    configuration = Configuration()
                    ^^^^^^^^^^^^^
NameError: name 'Configuration' is not defined

During handling of the above exception, another exception occurred:

Traceback (most recent call last):
  File "C:\Users\admin\AppData\Local\Programs\Python\Python312\Lib\site-packages\django\core\handlers\exception.py", line 55, in inner
    response = get_response(request)
               ^^^^^^^^^^^^^^^^^^^^^
  File "C:\Users\admin\AppData\Local\Programs\Python\Python312\Lib\site-packages\django\core\handlers\base.py", line 197, in _get_response
    response = wrapped_callback(request, *callback_args, **callback_kwargs)
               ^^^^^^^^^^^^^^^^^^^^^^^^^^^^^^^^^^^^^^^^^^^^^^^^^^^^^^^^^^^^
  File "C:\Users\admin\siteworks\core\views.py", line 138, in forgot_password
    return render(request, 'core/forgot_password.html', {'error': 'An error occurred. Please try again later.'})
           ^^^^^^^^^^^^^^^^^^^^^^^^^^^^^^^^^^^^^^^^^^^^^^^^^^^^^^^^^^^^^^^^^^^^^^^^^^^^^^^^^^^^^^^^^^^^^^^^^^^^^
  File "C:\Users\admin\AppData\Local\Programs\Python\Python312\Lib\site-packages\django\shortcuts.py", line 25, in render
    content = loader.render_to_string(template_name, context, request, using=using)
              ^^^^^^^^^^^^^^^^^^^^^^^^^^^^^^^^^^^^^^^^^^^^^^^^^^^^^^^^^^^^^^^^^^^^^
  File "C:\Users\admin\AppData\Local\Programs\Python\Python312\Lib\site-packages\django\template\loader.py", line 61, in render_to_string
    template = get_template(template_name, using=using)
               ^^^^^^^^^^^^^^^^^^^^^^^^^^^^^^^^^^^^^^^^
  File "C:\Users\admin\AppData\Local\Programs\Python\Python312\Lib\site-packages\django\template\loader.py", line 19, in get_template
    raise TemplateDoesNotExist(template_name, chain=chain)
django.template.exceptions.TemplateDoesNotExist: core/forgot_password.html
"POST /forgot-password/ HTTP/1.1" 500 90387
Internal Server Error: /forgot-password/
Traceback (most recent call last):
  File "C:\Users\admin\siteworks\core\views.py", line 114, in forgot_password
    configuration = Configuration()
                    ^^^^^^^^^^^^^
NameError: name 'Configuration' is not defined

During handling of the above exception, another exception occurred:

Traceback (most recent call last):
  File "C:\Users\admin\AppData\Local\Programs\Python\Python312\Lib\site-packages\django\core\handlers\exception.py", line 55, in inner
    response = get_response(request)
               ^^^^^^^^^^^^^^^^^^^^^
  File "C:\Users\admin\AppData\Local\Programs\Python\Python312\Lib\site-packages\django\core\handlers\base.py", line 197, in _get_response
    response = wrapped_callback(request, *callback_args, **callback_kwargs)
               ^^^^^^^^^^^^^^^^^^^^^^^^^^^^^^^^^^^^^^^^^^^^^^^^^^^^^^^^^^^^
  File "C:\Users\admin\siteworks\core\views.py", line 138, in forgot_password
    return render(request, 'core/templates/forgot_password.html', {'error': 'An error occurred. Please try again later.'})
           ^^^^^^^^^^^^^^^^^^^^^^^^^^^^^^^^^^^^^^^^^^^^^^^^^^^^^^^^^^^^^^^^^^^^^^^^^^^^^^^^^^^^^^^^^^^^^^^^^^^^^^^^^^^^^^^
  File "C:\Users\admin\AppData\Local\Programs\Python\Python312\Lib\site-packages\django\shortcuts.py", line 25, in render
    content = loader.render_to_string(template_name, context, request, using=using)
              ^^^^^^^^^^^^^^^^^^^^^^^^^^^^^^^^^^^^^^^^^^^^^^^^^^^^^^^^^^^^^^^^^^^^^
  File "C:\Users\admin\AppData\Local\Programs\Python\Python312\Lib\site-packages\django\template\loader.py", line 61, in render_to_string
    template = get_template(template_name, using=using)
               ^^^^^^^^^^^^^^^^^^^^^^^^^^^^^^^^^^^^^^^^
  File "C:\Users\admin\AppData\Local\Programs\Python\Python312\Lib\site-packages\django\template\loader.py", line 19, in get_template
    raise TemplateDoesNotExist(template_name, chain=chain)
django.template.exceptions.TemplateDoesNotExist: core/templates/forgot_password.html
"POST /forgot-password/ HTTP/1.1" 500 90617
<<<<<<< HEAD
Internal Server Error: /login/
Traceback (most recent call last):
  File "C:\Users\HomePC\AppData\Local\Programs\Python\Python313\Lib\site-packages\django\db\backends\utils.py", line 105, in _execute
    return self.cursor.execute(sql, params)
           ~~~~~~~~~~~~~~~~~~~^^^^^^^^^^^^^
  File "C:\Users\HomePC\AppData\Local\Programs\Python\Python313\Lib\site-packages\django\db\backends\sqlite3\base.py", line 354, in execute
    return super().execute(query, params)
           ~~~~~~~~~~~~~~~^^^^^^^^^^^^^^^
sqlite3.OperationalError: no such column: core_profile.phone_number

The above exception was the direct cause of the following exception:

Traceback (most recent call last):
  File "C:\Users\HomePC\AppData\Local\Programs\Python\Python313\Lib\site-packages\django\core\handlers\exception.py", line 55, in inner
    response = get_response(request)
  File "C:\Users\HomePC\AppData\Local\Programs\Python\Python313\Lib\site-packages\django\core\handlers\base.py", line 197, in _get_response
    response = wrapped_callback(request, *callback_args, **callback_kwargs)
  File "C:\Users\HomePC\Desktop\siteworks\core\views.py", line 64, in login_view
    profile = Profile.objects.get(user=user)
  File "C:\Users\HomePC\AppData\Local\Programs\Python\Python313\Lib\site-packages\django\db\models\manager.py", line 87, in manager_method
    return getattr(self.get_queryset(), name)(*args, **kwargs)
           ~~~~~~~~~~~~~~~~~~~~~~~~~~~~~~~~~~^^^^^^^^^^^^^^^^^
  File "C:\Users\HomePC\AppData\Local\Programs\Python\Python313\Lib\site-packages\django\db\models\query.py", line 645, in get
    num = len(clone)
  File "C:\Users\HomePC\AppData\Local\Programs\Python\Python313\Lib\site-packages\django\db\models\query.py", line 382, in __len__
    self._fetch_all()
    ~~~~~~~~~~~~~~~^^
  File "C:\Users\HomePC\AppData\Local\Programs\Python\Python313\Lib\site-packages\django\db\models\query.py", line 1928, in _fetch_all
    self._result_cache = list(self._iterable_class(self))
                         ~~~~^^^^^^^^^^^^^^^^^^^^^^^^^^^^
  File "C:\Users\HomePC\AppData\Local\Programs\Python\Python313\Lib\site-packages\django\db\models\query.py", line 91, in __iter__
    results = compiler.execute_sql(
        chunked_fetch=self.chunked_fetch, chunk_size=self.chunk_size
    )
  File "C:\Users\HomePC\AppData\Local\Programs\Python\Python313\Lib\site-packages\django\db\models\sql\compiler.py", line 1574, in execute_sql
    cursor.execute(sql, params)
    ~~~~~~~~~~~~~~^^^^^^^^^^^^^
  File "C:\Users\HomePC\AppData\Local\Programs\Python\Python313\Lib\site-packages\django\db\backends\utils.py", line 122, in execute
    return super().execute(sql, params)
           ~~~~~~~~~~~~~~~^^^^^^^^^^^^^
  File "C:\Users\HomePC\AppData\Local\Programs\Python\Python313\Lib\site-packages\django\db\backends\utils.py", line 79, in execute
    return self._execute_with_wrappers(
           ~~~~~~~~~~~~~~~~~~~~~~~~~~~^
        sql, params, many=False, executor=self._execute
        ^^^^^^^^^^^^^^^^^^^^^^^^^^^^^^^^^^^^^^^^^^^^^^^
    )
    ^
  File "C:\Users\HomePC\AppData\Local\Programs\Python\Python313\Lib\site-packages\django\db\backends\utils.py", line 92, in _execute_with_wrappers
    return executor(sql, params, many, context)
  File "C:\Users\HomePC\AppData\Local\Programs\Python\Python313\Lib\site-packages\django\db\backends\utils.py", line 100, in _execute
    with self.db.wrap_database_errors:
         ^^^^^^^^^^^^^^^^^^^^^^^^^^^^
  File "C:\Users\HomePC\AppData\Local\Programs\Python\Python313\Lib\site-packages\django\db\utils.py", line 91, in __exit__
    raise dj_exc_value.with_traceback(traceback) from exc_value
  File "C:\Users\HomePC\AppData\Local\Programs\Python\Python313\Lib\site-packages\django\db\backends\utils.py", line 105, in _execute
    return self.cursor.execute(sql, params)
           ~~~~~~~~~~~~~~~~~~~^^^^^^^^^^^^^
  File "C:\Users\HomePC\AppData\Local\Programs\Python\Python313\Lib\site-packages\django\db\backends\sqlite3\base.py", line 354, in execute
    return super().execute(query, params)
           ~~~~~~~~~~~~~~~^^^^^^^^^^^^^^^
django.db.utils.OperationalError: no such column: core_profile.phone_number
Internal Server Error: /login/
Traceback (most recent call last):
  File "C:\Users\HomePC\AppData\Local\Programs\Python\Python313\Lib\site-packages\django\db\backends\utils.py", line 105, in _execute
    return self.cursor.execute(sql, params)
           ~~~~~~~~~~~~~~~~~~~^^^^^^^^^^^^^
  File "C:\Users\HomePC\AppData\Local\Programs\Python\Python313\Lib\site-packages\django\db\backends\sqlite3\base.py", line 354, in execute
    return super().execute(query, params)
           ~~~~~~~~~~~~~~~^^^^^^^^^^^^^^^
sqlite3.OperationalError: no such column: core_profile.phone_number

The above exception was the direct cause of the following exception:

Traceback (most recent call last):
  File "C:\Users\HomePC\AppData\Local\Programs\Python\Python313\Lib\site-packages\django\core\handlers\exception.py", line 55, in inner
    response = get_response(request)
  File "C:\Users\HomePC\AppData\Local\Programs\Python\Python313\Lib\site-packages\django\core\handlers\base.py", line 197, in _get_response
    response = wrapped_callback(request, *callback_args, **callback_kwargs)
  File "C:\Users\HomePC\Desktop\siteworks\core\views.py", line 64, in login_view
    profile = Profile.objects.get(user=user)
  File "C:\Users\HomePC\AppData\Local\Programs\Python\Python313\Lib\site-packages\django\db\models\manager.py", line 87, in manager_method
    return getattr(self.get_queryset(), name)(*args, **kwargs)
           ~~~~~~~~~~~~~~~~~~~~~~~~~~~~~~~~~~^^^^^^^^^^^^^^^^^
  File "C:\Users\HomePC\AppData\Local\Programs\Python\Python313\Lib\site-packages\django\db\models\query.py", line 645, in get
    num = len(clone)
  File "C:\Users\HomePC\AppData\Local\Programs\Python\Python313\Lib\site-packages\django\db\models\query.py", line 382, in __len__
    self._fetch_all()
    ~~~~~~~~~~~~~~~^^
  File "C:\Users\HomePC\AppData\Local\Programs\Python\Python313\Lib\site-packages\django\db\models\query.py", line 1928, in _fetch_all
    self._result_cache = list(self._iterable_class(self))
                         ~~~~^^^^^^^^^^^^^^^^^^^^^^^^^^^^
  File "C:\Users\HomePC\AppData\Local\Programs\Python\Python313\Lib\site-packages\django\db\models\query.py", line 91, in __iter__
    results = compiler.execute_sql(
        chunked_fetch=self.chunked_fetch, chunk_size=self.chunk_size
    )
  File "C:\Users\HomePC\AppData\Local\Programs\Python\Python313\Lib\site-packages\django\db\models\sql\compiler.py", line 1574, in execute_sql
    cursor.execute(sql, params)
    ~~~~~~~~~~~~~~^^^^^^^^^^^^^
  File "C:\Users\HomePC\AppData\Local\Programs\Python\Python313\Lib\site-packages\django\db\backends\utils.py", line 122, in execute
    return super().execute(sql, params)
           ~~~~~~~~~~~~~~~^^^^^^^^^^^^^
  File "C:\Users\HomePC\AppData\Local\Programs\Python\Python313\Lib\site-packages\django\db\backends\utils.py", line 79, in execute
    return self._execute_with_wrappers(
           ~~~~~~~~~~~~~~~~~~~~~~~~~~~^
        sql, params, many=False, executor=self._execute
        ^^^^^^^^^^^^^^^^^^^^^^^^^^^^^^^^^^^^^^^^^^^^^^^
    )
    ^
  File "C:\Users\HomePC\AppData\Local\Programs\Python\Python313\Lib\site-packages\django\db\backends\utils.py", line 92, in _execute_with_wrappers
    return executor(sql, params, many, context)
  File "C:\Users\HomePC\AppData\Local\Programs\Python\Python313\Lib\site-packages\django\db\backends\utils.py", line 100, in _execute
    with self.db.wrap_database_errors:
         ^^^^^^^^^^^^^^^^^^^^^^^^^^^^
  File "C:\Users\HomePC\AppData\Local\Programs\Python\Python313\Lib\site-packages\django\db\utils.py", line 91, in __exit__
    raise dj_exc_value.with_traceback(traceback) from exc_value
  File "C:\Users\HomePC\AppData\Local\Programs\Python\Python313\Lib\site-packages\django\db\backends\utils.py", line 105, in _execute
    return self.cursor.execute(sql, params)
           ~~~~~~~~~~~~~~~~~~~^^^^^^^^^^^^^
  File "C:\Users\HomePC\AppData\Local\Programs\Python\Python313\Lib\site-packages\django\db\backends\sqlite3\base.py", line 354, in execute
    return super().execute(query, params)
           ~~~~~~~~~~~~~~~^^^^^^^^^^^^^^^
django.db.utils.OperationalError: no such column: core_profile.phone_number
"POST /login/ HTTP/1.1" 500 141244
"GET / HTTP/1.1" 500 0
"GET / HTTP/1.1" 500 0
"GET /static/assets/favicon.ico HTTP/1.1" 500 0
"GET / HTTP/1.1" 500 0
"GET / HTTP/1.1" 500 0
"GET /static/js/scripts.js HTTP/1.1" 500 0
"GET /static/css/styles.css HTTP/1.1" 500 0
"GET / HTTP/1.1" 500 0
"GET /static/js/scripts.js HTTP/1.1" 500 0
"GET /static/css/styles.css HTTP/1.1" 500 0
=======
>>>>>>> 83054005a7a4cef253d219ed271d224c9ffcacc6
"GET / HTTP/1.1" 500 0
"GET / HTTP/1.1" 500 0
"GET / HTTP/1.1" 500 0
"GET / HTTP/1.1" 500 0
Internal Server Error: /chatbot/get-response/
Traceback (most recent call last):
  File "C:\Users\HomePC\AppData\Local\Programs\Python\Python313\Lib\site-packages\urllib3\connection.py", line 198, in _new_conn
    sock = connection.create_connection(
        (self._dns_host, self.port),
    ...<2 lines>...
        socket_options=self.socket_options,
    )
  File "C:\Users\HomePC\AppData\Local\Programs\Python\Python313\Lib\site-packages\urllib3\util\connection.py", line 85, in create_connection
    raise err
  File "C:\Users\HomePC\AppData\Local\Programs\Python\Python313\Lib\site-packages\urllib3\util\connection.py", line 73, in create_connection
    sock.connect(sa)
    ~~~~~~~~~~~~^^^^
ConnectionRefusedError: [WinError 10061] No connection could be made because the target machine actively refused it

The above exception was the direct cause of the following exception:

Traceback (most recent call last):
  File "C:\Users\HomePC\AppData\Local\Programs\Python\Python313\Lib\site-packages\urllib3\connectionpool.py", line 787, in urlopen
    response = self._make_request(
        conn,
    ...<10 lines>...
        **response_kw,
    )
  File "C:\Users\HomePC\AppData\Local\Programs\Python\Python313\Lib\site-packages\urllib3\connectionpool.py", line 493, in _make_request
    conn.request(
    ~~~~~~~~~~~~^
        method,
        ^^^^^^^
    ...<6 lines>...
        enforce_content_length=enforce_content_length,
        ^^^^^^^^^^^^^^^^^^^^^^^^^^^^^^^^^^^^^^^^^^^^^^
    )
    ^
  File "C:\Users\HomePC\AppData\Local\Programs\Python\Python313\Lib\site-packages\urllib3\connection.py", line 445, in request
    self.endheaders()
    ~~~~~~~~~~~~~~~^^
  File "C:\Users\HomePC\AppData\Local\Programs\Python\Python313\Lib\http\client.py", line 1333, in endheaders
    self._send_output(message_body, encode_chunked=encode_chunked)
    ~~~~~~~~~~~~~~~~~^^^^^^^^^^^^^^^^^^^^^^^^^^^^^^^^^^^^^^^^^^^^^
  File "C:\Users\HomePC\AppData\Local\Programs\Python\Python313\Lib\http\client.py", line 1093, in _send_output
    self.send(msg)
    ~~~~~~~~~^^^^^
  File "C:\Users\HomePC\AppData\Local\Programs\Python\Python313\Lib\http\client.py", line 1037, in send
    self.connect()
    ~~~~~~~~~~~~^^
  File "C:\Users\HomePC\AppData\Local\Programs\Python\Python313\Lib\site-packages\urllib3\connection.py", line 276, in connect
    self.sock = self._new_conn()
                ~~~~~~~~~~~~~~^^
  File "C:\Users\HomePC\AppData\Local\Programs\Python\Python313\Lib\site-packages\urllib3\connection.py", line 213, in _new_conn
    raise NewConnectionError(
        self, f"Failed to establish a new connection: {e}"
    ) from e
urllib3.exceptions.NewConnectionError: <urllib3.connection.HTTPConnection object at 0x00000268E8E41BE0>: Failed to establish a new connection: [WinError 10061] No connection could be made because the target machine actively refused it

The above exception was the direct cause of the following exception:

Traceback (most recent call last):
  File "C:\Users\HomePC\AppData\Local\Programs\Python\Python313\Lib\site-packages\requests\adapters.py", line 667, in send
    resp = conn.urlopen(
        method=request.method,
    ...<9 lines>...
        chunked=chunked,
    )
  File "C:\Users\HomePC\AppData\Local\Programs\Python\Python313\Lib\site-packages\urllib3\connectionpool.py", line 841, in urlopen
    retries = retries.increment(
        method, url, error=new_e, _pool=self, _stacktrace=sys.exc_info()[2]
    )
  File "C:\Users\HomePC\AppData\Local\Programs\Python\Python313\Lib\site-packages\urllib3\util\retry.py", line 519, in increment
    raise MaxRetryError(_pool, url, reason) from reason  # type: ignore[arg-type]
    ^^^^^^^^^^^^^^^^^^^^^^^^^^^^^^^^^^^^^^^^^^^^^^^^^^^
urllib3.exceptions.MaxRetryError: HTTPConnectionPool(host='127.0.0.1', port=5000): Max retries exceeded with url: /get-response?message=hello&role=default (Caused by NewConnectionError('<urllib3.connection.HTTPConnection object at 0x00000268E8E41BE0>: Failed to establish a new connection: [WinError 10061] No connection could be made because the target machine actively refused it'))

During handling of the above exception, another exception occurred:

Traceback (most recent call last):
  File "C:\Users\HomePC\AppData\Local\Programs\Python\Python313\Lib\site-packages\django\core\handlers\exception.py", line 55, in inner
    response = get_response(request)
  File "C:\Users\HomePC\AppData\Local\Programs\Python\Python313\Lib\site-packages\django\core\handlers\base.py", line 197, in _get_response
    response = wrapped_callback(request, *callback_args, **callback_kwargs)
  File "C:\Users\HomePC\Desktop\siteworks\chatbot\views.py", line 47, in chatbot_response
    response = requests.get(flask_url, params={'message': user_message, 'role': role})
  File "C:\Users\HomePC\AppData\Local\Programs\Python\Python313\Lib\site-packages\requests\api.py", line 73, in get
    return request("get", url, params=params, **kwargs)
  File "C:\Users\HomePC\AppData\Local\Programs\Python\Python313\Lib\site-packages\requests\api.py", line 59, in request
    return session.request(method=method, url=url, **kwargs)
           ~~~~~~~~~~~~~~~^^^^^^^^^^^^^^^^^^^^^^^^^^^^^^^^^^
  File "C:\Users\HomePC\AppData\Local\Programs\Python\Python313\Lib\site-packages\requests\sessions.py", line 589, in request
    resp = self.send(prep, **send_kwargs)
  File "C:\Users\HomePC\AppData\Local\Programs\Python\Python313\Lib\site-packages\requests\sessions.py", line 703, in send
    r = adapter.send(request, **kwargs)
  File "C:\Users\HomePC\AppData\Local\Programs\Python\Python313\Lib\site-packages\requests\adapters.py", line 700, in send
    raise ConnectionError(e, request=request)
requests.exceptions.ConnectionError: HTTPConnectionPool(host='127.0.0.1', port=5000): Max retries exceeded with url: /get-response?message=hello&role=default (Caused by NewConnectionError('<urllib3.connection.HTTPConnection object at 0x00000268E8E41BE0>: Failed to establish a new connection: [WinError 10061] No connection could be made because the target machine actively refused it'))
"GET /chatbot/get-response/?message=hello&role=default HTTP/1.1" 500 175905
Internal Server Error: /chatbot/get-response/
Traceback (most recent call last):
  File "C:\Users\HomePC\AppData\Local\Programs\Python\Python313\Lib\site-packages\urllib3\connection.py", line 198, in _new_conn
    sock = connection.create_connection(
        (self._dns_host, self.port),
    ...<2 lines>...
        socket_options=self.socket_options,
    )
  File "C:\Users\HomePC\AppData\Local\Programs\Python\Python313\Lib\site-packages\urllib3\util\connection.py", line 85, in create_connection
    raise err
  File "C:\Users\HomePC\AppData\Local\Programs\Python\Python313\Lib\site-packages\urllib3\util\connection.py", line 73, in create_connection
    sock.connect(sa)
    ~~~~~~~~~~~~^^^^
ConnectionRefusedError: [WinError 10061] No connection could be made because the target machine actively refused it

The above exception was the direct cause of the following exception:

Traceback (most recent call last):
  File "C:\Users\HomePC\AppData\Local\Programs\Python\Python313\Lib\site-packages\urllib3\connectionpool.py", line 787, in urlopen
    response = self._make_request(
        conn,
    ...<10 lines>...
        **response_kw,
    )
  File "C:\Users\HomePC\AppData\Local\Programs\Python\Python313\Lib\site-packages\urllib3\connectionpool.py", line 493, in _make_request
    conn.request(
    ~~~~~~~~~~~~^
        method,
        ^^^^^^^
    ...<6 lines>...
        enforce_content_length=enforce_content_length,
        ^^^^^^^^^^^^^^^^^^^^^^^^^^^^^^^^^^^^^^^^^^^^^^
    )
    ^
  File "C:\Users\HomePC\AppData\Local\Programs\Python\Python313\Lib\site-packages\urllib3\connection.py", line 445, in request
    self.endheaders()
    ~~~~~~~~~~~~~~~^^
  File "C:\Users\HomePC\AppData\Local\Programs\Python\Python313\Lib\http\client.py", line 1333, in endheaders
    self._send_output(message_body, encode_chunked=encode_chunked)
    ~~~~~~~~~~~~~~~~~^^^^^^^^^^^^^^^^^^^^^^^^^^^^^^^^^^^^^^^^^^^^^
  File "C:\Users\HomePC\AppData\Local\Programs\Python\Python313\Lib\http\client.py", line 1093, in _send_output
    self.send(msg)
    ~~~~~~~~~^^^^^
  File "C:\Users\HomePC\AppData\Local\Programs\Python\Python313\Lib\http\client.py", line 1037, in send
    self.connect()
    ~~~~~~~~~~~~^^
  File "C:\Users\HomePC\AppData\Local\Programs\Python\Python313\Lib\site-packages\urllib3\connection.py", line 276, in connect
    self.sock = self._new_conn()
                ~~~~~~~~~~~~~~^^
  File "C:\Users\HomePC\AppData\Local\Programs\Python\Python313\Lib\site-packages\urllib3\connection.py", line 213, in _new_conn
    raise NewConnectionError(
        self, f"Failed to establish a new connection: {e}"
    ) from e
urllib3.exceptions.NewConnectionError: <urllib3.connection.HTTPConnection object at 0x00000268E8E979D0>: Failed to establish a new connection: [WinError 10061] No connection could be made because the target machine actively refused it

The above exception was the direct cause of the following exception:

Traceback (most recent call last):
  File "C:\Users\HomePC\AppData\Local\Programs\Python\Python313\Lib\site-packages\requests\adapters.py", line 667, in send
    resp = conn.urlopen(
        method=request.method,
    ...<9 lines>...
        chunked=chunked,
    )
  File "C:\Users\HomePC\AppData\Local\Programs\Python\Python313\Lib\site-packages\urllib3\connectionpool.py", line 841, in urlopen
    retries = retries.increment(
        method, url, error=new_e, _pool=self, _stacktrace=sys.exc_info()[2]
    )
  File "C:\Users\HomePC\AppData\Local\Programs\Python\Python313\Lib\site-packages\urllib3\util\retry.py", line 519, in increment
    raise MaxRetryError(_pool, url, reason) from reason  # type: ignore[arg-type]
    ^^^^^^^^^^^^^^^^^^^^^^^^^^^^^^^^^^^^^^^^^^^^^^^^^^^
urllib3.exceptions.MaxRetryError: HTTPConnectionPool(host='127.0.0.1', port=5000): Max retries exceeded with url: /get-response?message=who+are+you&role=default (Caused by NewConnectionError('<urllib3.connection.HTTPConnection object at 0x00000268E8E979D0>: Failed to establish a new connection: [WinError 10061] No connection could be made because the target machine actively refused it'))

During handling of the above exception, another exception occurred:

Traceback (most recent call last):
  File "C:\Users\HomePC\AppData\Local\Programs\Python\Python313\Lib\site-packages\django\core\handlers\exception.py", line 55, in inner
    response = get_response(request)
  File "C:\Users\HomePC\AppData\Local\Programs\Python\Python313\Lib\site-packages\django\core\handlers\base.py", line 197, in _get_response
    response = wrapped_callback(request, *callback_args, **callback_kwargs)
  File "C:\Users\HomePC\Desktop\siteworks\chatbot\views.py", line 47, in chatbot_response
    response = requests.get(flask_url, params={'message': user_message, 'role': role})
  File "C:\Users\HomePC\AppData\Local\Programs\Python\Python313\Lib\site-packages\requests\api.py", line 73, in get
    return request("get", url, params=params, **kwargs)
  File "C:\Users\HomePC\AppData\Local\Programs\Python\Python313\Lib\site-packages\requests\api.py", line 59, in request
    return session.request(method=method, url=url, **kwargs)
           ~~~~~~~~~~~~~~~^^^^^^^^^^^^^^^^^^^^^^^^^^^^^^^^^^
  File "C:\Users\HomePC\AppData\Local\Programs\Python\Python313\Lib\site-packages\requests\sessions.py", line 589, in request
    resp = self.send(prep, **send_kwargs)
  File "C:\Users\HomePC\AppData\Local\Programs\Python\Python313\Lib\site-packages\requests\sessions.py", line 703, in send
    r = adapter.send(request, **kwargs)
  File "C:\Users\HomePC\AppData\Local\Programs\Python\Python313\Lib\site-packages\requests\adapters.py", line 700, in send
    raise ConnectionError(e, request=request)
requests.exceptions.ConnectionError: HTTPConnectionPool(host='127.0.0.1', port=5000): Max retries exceeded with url: /get-response?message=who+are+you&role=default (Caused by NewConnectionError('<urllib3.connection.HTTPConnection object at 0x00000268E8E979D0>: Failed to establish a new connection: [WinError 10061] No connection could be made because the target machine actively refused it'))
"GET /chatbot/get-response/?message=who%20are%20you&role=default HTTP/1.1" 500 176104
"GET /chatbot/get-response/?message=who%20are%20you&role=default HTTP/1.1" 500 0
"GET /chatbot/get-response/?message=hello&role=default HTTP/1.1" 500 0
"GET / HTTP/1.1" 500 0
"GET / HTTP/1.1" 500 0
"GET /login/ HTTP/1.1" 500 0
"GET /static/js/login.js HTTP/1.1" 500 0
"GET /static/css/login.css HTTP/1.1" 500 0
"POST /login/ HTTP/1.1" 500 0
